Workbook

Sheet ПРОСПЕКТА_брики
B1: Регион ММХ | C1: Область | D1: Менеджер | E1: Сотрудник | F1: Эшелон | G1: Брик | H1: Оценка (мп.), % | I1: Оценка общая (рук.), % | J1: Оценка эффективности коммуникации (рук.), % | K1: Оценка навыки продаж (рук.), % | L1: Динамика региона
A2: 0 | B2: Москва | C2: ПроРеспи М4 Восток | D2: Мальцева А.А. | E2: Абазова А.С. | F2: 8. ПРОРЕСПИ_РФ | H2: 0.55882353 | I2: 0.55882353 | J2: =VLOOKUP(E2,'Эффективная коммуникация оценка'!$E$1:$P$297,12,0) -> 0.4 | K2: =VLOOKUP(E2,'навыки техники продаж оценка'!$E$2:$P$297,12,0) -> 0.58333333 | L2: 52.117264
A3: 16 | B3: Москва | C3: ПроРеспи М10 Юго-Запад | D3: Кавунова И.Г. | E3: Антонов Д.А. | F3: 8. ПРОРЕСПИ_РФ | H3: 0.55882353 | I3: 0.64705882 | J3: =VLOOKUP(E3,'Эффективная коммуникация оценка'!$E$1:$P$297,12,0) -> 0.65 | K3: =VLOOKUP(E3,'навыки техники продаж оценка'!$E$2:$P$297,12,0) -> 0.58333333 | L3: 23.721436
A4: 21 | B4: Москва | C4: ПроРеспи М16 Север | D4: Котельникова Е.Б. | E4: Бодрова А.В. | F4: 8. ПРОРЕСПИ_РФ | H4: 0.72058824 | I4: 0.73529412 | J4: =VLOOKUP(E4,'Эффективная коммуникация оценка'!$E$1:$P$297,12,0) -> 0.65 | K4: =VLOOKUP(E4,'навыки техники продаж оценка'!$E$2:$P$297,12,0) -> 0.75 | L4: 43.225331
A5: 47 | B5: Москва | C5: ПроРеспи МО9 ТиНАО | D5: Скрылев А.В. | E5: Прищеп Л.П. | F5: 8. ПРОРЕСПИ_РФ | H5: 0.60294118 | I5: 0.75 | J5: =VLOOKUP(E5,'Эффективная коммуникация оценка'!$E$1:$P$297,12,0) -> 0.8 | K5: =VLOOKUP(E5,'навыки техники продаж оценка'!$E$2:$P$297,12,0) -> 0.66666667 | L5: 50.302623
A6: 60 | B6: Москва | C6: ПроРеспи М1 Восток | D6: Мальцева А.А. | E6: Афанасьева Ю.А. | F6: 8. ПРОРЕСПИ_РФ | H6: 0.52941176 | I6: 0.66176471 | J6: =VLOOKUP(E6,'Эффективная коммуникация оценка'!$E$1:$P$297,12,0) -> 0.7 | K6: =VLOOKUP(E6,'навыки техники продаж оценка'!$E$2:$P$297,12,0) -> 0.66666667 | L6: 36.445444
A7: 75 | B7: Москва | C7: ПроРеспи М14 Юг | D7: Кавунова И.Г. | E7: Семенова Т.Н. | F7: 8. ПРОРЕСПИ_РФ | H7: 0.52941176 | I7: 0.58823529 | J7: =VLOOKUP(E7,'Эффективная коммуникация оценка'!$E$1:$P$297,12,0) -> 0.6 | K7: =VLOOKUP(E7,'навыки техники продаж оценка'!$E$2:$P$297,12,0) -> 0.5 | L7: 15.123457
A8: 78 | B8: Москва | C8: ПроРеспи М11 Юго-Запад | D8: Кавунова И.Г. | E8: Разгуляева Т.А. | F8: 8. ПРОРЕСПИ_РФ | H8: 0.58823529 | I8: 0.64705882 | J8: =VLOOKUP(E8,'Эффективная коммуникация оценка'!$E$1:$P$297,12,0) -> 0.6 | K8: =VLOOKUP(E8,'навыки техники продаж оценка'!$E$2:$P$297,12,0) -> 0.58333333 | L8: 29.177378
A9: 86 | B9: Москва | C9: ПроРеспи М15 Север | D9: Котельникова Е.Б. | E9: Каминский Н.В. | F9: 8. ПРОРЕСПИ_РФ | H9: 0.5 | I9: 0.66176471 | J9: =VLOOKUP(E9,'Эффективная коммуникация оценка'!$E$1:$P$297,12,0) -> 0.55 | K9: =VLOOKUP(E9,'навыки техники продаж оценка'!$E$2:$P$297,12,0) -> 0.5 | L9: 53.347969
A10: 95 | B10: Москва | C10: ПроРеспи М2 Юго-Восток | D10: Мальцева А.А. | E10: Дмитраш А.В. | F10: 8. ПРОРЕСПИ_РФ | H10: 0.35294118 | I10: 0.54411765 | J10: =VLOOKUP(E10,'Эффективная коммуникация оценка'!$E$1:$P$297,12,0) -> 0.55 | K10: =VLOOKUP(E10,'навыки техники продаж оценка'!$E$2:$P$297,12,0) -> 0.58333333 | L10: 27.066667
A11: 99 | B11: Москва | C11: ПроСпец М5 Центр | D11: Мальцева А.А. | E11: Козырева Е.Н. | F11: 8. ПРОСПЕЦ_РФ | H11: 0.55882353 | I11: 0.52941176 | J11: =VLOOKUP(E11,'Эффективная коммуникация оценка'!$E$1:$P$297,12,0) -> 0.6 | K11: =VLOOKUP(E11,'навыки техники продаж оценка'!$E$2:$P$297,12,0) -> 0.5 | L11: 33.369099
A12: 100 | B12: Москва | C12: ПроРеспи М20 Северо-Восток | D12: Котельникова Е.Б. | E12: Кабатова И.А. | F12: 8. ПРОРЕСПИ_РФ | H12: 0.66176471 | I12: 0.69117647 | J12: =VLOOKUP(E12,'Эффективная коммуникация оценка'!$E$1:$P$297,12,0) -> 0.7 | K12: =VLOOKUP(E12,'навыки техники продаж оценка'!$E$2:$P$297,12,0) -> 0.75 | L12: 70.493129
A13: 112 | B13: Москва | C13: ПроСпец М8 Юго- Восток | D13: Мальцева А.А. | E13: Кравцова А.С. | F13: 8. ПРОСПЕЦ_РФ | I13: 0.51470588 | J13: =VLOOKUP(E13,'Эффективная коммуникация оценка'!$E$1:$P$297,12,0) -> 0.55 | K13: =VLOOKUP(E13,'навыки техники продаж оценка'!$E$2:$P$297,12,0) -> 0.5 | L13: 23.695261
A14: 130 | B14: Москва | C14: ПроРеспи М7 Запад | D14: Кавунова И.Г. | E14: Иванова А.В. | F14: 8. ПРОРЕСПИ_РФ | H14: 0.54411765 | I14: 0.60294118 | J14: =VLOOKUP(E14,'Эффективная коммуникация оценка'!$E$1:$P$297,12,0) -> 0.65 | K14: =VLOOKUP(E14,'навыки техники продаж оценка'!$E$2:$P$297,12,0) -> 0.58333333 | L14: 23.989397
A15: 134 | B15: Москва | C15: ПроСпец М6 Центр | D15: Мальцева А.А. | E15: Нефедова Э.С. | F15: 8. ПРОСПЕЦ_РФ | I15: 0.44117647 | J15: =VLOOKUP(E15,'Эффективная коммуникация оценка'!$E$1:$P$297,12,0) -> 0.4 | K15: =VLOOKUP(E15,'навыки техники продаж оценка'!$E$2:$P$297,12,0) -> 0.25 | L15: 30.995792
A16: 159 | B16: Москва | C16: ПроСпец М3 Юг | D16: Кавунова И.Г. | E16: Стрельникова М.Ю. | F16: 8. ПРОСПЕЦ_РФ | I16: 0.73529412 | J16: =VLOOKUP(E16,'Эффективная коммуникация оценка'!$E$1:$P$297,12,0) -> 0.7 | K16: =VLOOKUP(E16,'навыки техники продаж оценка'!$E$2:$P$297,12,0) -> 0.75 | L16: 20.444444
A17: 168 | B17: Москва | C17: ПроРеспи М3 Восток | D17: Котельникова Е.Б. | E17: Каманова А.А. | F17: 8. ПРОРЕСПИ_РФ | H17: 0.54411765 | I17: 0.64705882 | J17: =VLOOKUP(E17,'Эффективная коммуникация оценка'!$E$1:$P$297,12,0) -> 0.65 | K17: =VLOOKUP(E17,'навыки техники продаж оценка'!$E$2:$P$297,12,0) -> 0.5 | L17: 38.821138
A18: 169 | B18: Москва | C18: ПроСпец М11 Северо-Восток | D18: Котельникова Е.Б. | E18: Егорова Т.И. | F18: 8. ПРОСПЕЦ_РФ | H18: 0.48529412 | I18: 0.67647059 | J18: =VLOOKUP(E18,'Эффективная коммуникация оценка'!$E$1:$P$297,12,0) -> 0.65 | K18: =VLOOKUP(E18,'навыки техники продаж оценка'!$E$2:$P$297,12,0) -> 0.58333333 | L18: 55.750118
A19: 190 | B19: Москва | C19: ПроСпец МО8 ТиНАО | D19: Скрылев А.В. | E19: Гарматин В.О. | F19: 8. ПРОСПЕЦ_РФ | I19: 0.5 | J19: =VLOOKUP(E19,'Эффективная коммуникация оценка'!$E$1:$P$297,12,0) -> 0.4 | K19: =VLOOKUP(E19,'навыки техники продаж оценка'!$E$2:$P$297,12,0) -> 0.58333333 | L19: 50.302623
A20: 202 | B20: Москва | C20: ПроРеспи М17 Северо-Запад | D20: Котельникова Е.Б. | E20: Грязнова О.А. | F20: 8. ПРОРЕСПИ_РФ | H20: 0.69117647 | I20: 0.69117647 | J20: =VLOOKUP(E20,'Эффективная коммуникация оценка'!$E$1:$P$297,12,0) -> 0.6 | K20: =VLOOKUP(E20,'навыки техники продаж оценка'!$E$2:$P$297,12,0) -> 0.58333333 | L20: 35.651214
A21: 210 | B21: Москва | C21: ПроРеспи М12 Юг | D21: Кавунова И.Г. | E21: Селезнева Ю.В. | F21: 8. ПРОРЕСПИ_РФ | H21: 0.57352941 | I21: 0.55882353 | J21: =VLOOKUP(E21,'Эффективная коммуникация оценка'!$E$1:$P$297,12,0) -> 0.55 | K21: =VLOOKUP(E21,'навыки техники продаж оценка'!$E$2:$P$297,12,0) -> 0.66666667 | L21: 29.374337
A22: 212 | B22: Москва | C22: ПроРеспи М5 Центр | D22: Мальцева А.А. | E22: Юрова А.В. | F22: 8. ПРОРЕСПИ_РФ | H22: 0.5 | I22: 0.60294118 | J22: =VLOOKUP(E22,'Эффективная коммуникация оценка'!$E$1:$P$297,12,0) -> 0.6 | K22: =VLOOKUP(E22,'навыки техники продаж оценка'!$E$2:$P$297,12,0) -> 0.58333333 | L22: 30.995792
A23: 218 | B23: Москва | C23: ПроСпец М10 Восток-Северо-Восток | D23: Котельникова Е.Б. | E23: Касимова М.М. | F23: 8. ПРОСПЕЦ_РФ | H23: 0.75 | I23: 0.63235294 | J23: =VLOOKUP(E23,'Эффективная коммуникация оценка'!$E$1:$P$297,12,0) -> 0.8 | K23: =VLOOKUP(E23,'навыки техники продаж оценка'!$E$2:$P$297,12,0) -> 0.58333333 | L23: 39.593496
A24: 219 | B24: Москва | C24: ПроРеспи М6 Центр | D24: Мальцева А.А. | E24: Шебалкова Т.Н. | F24: 8. ПРОРЕСПИ_РФ | H24: 0.60294118 | I24: 0.83823529 | J24: =VLOOKUP(E24,'Эффективная коммуникация оценка'!$E$1:$P$297,12,0) -> 0.85 | K24: =VLOOKUP(E24,'навыки техники продаж оценка'!$E$2:$P$297,12,0) -> 0.91666667 | L24: 33.369099
A25: 234 | B25: Москва | C25: ПроСпец М7 Восток | D25: Мальцева А.А. | E25: Сагиндыкова Д.А. | F25: 8. ПРОСПЕЦ_РФ | H25: 0.42647059 | I25: 0.58823529 | J25: =VLOOKUP(E25,'Эффективная коммуникация оценка'!$E$1:$P$297,12,0) -> 0.55 | K25: =VLOOKUP(E25,'навыки техники продаж оценка'!$E$2:$P$297,12,0) -> 0.58333333 | L25: 42.105263
A26: 236 | B26: Москва | C26: ПроСпец М9 Юго- Восток-Юг | D26: Мальцева А.А. | E26: Наумова А.А. | F26: 8. ПРОСПЕЦ_РФ | I26: 0.69117647 | J26: =VLOOKUP(E26,'Эффективная коммуникация оценка'!$E$1:$P$297,12,0) -> 0.85 | K26: =VLOOKUP(E26,'навыки техники продаж оценка'!$E$2:$P$297,12,0) -> 0.58333333 | L26: 46.343975
A27: 240 | B27: Москва | C27: ПроСпец МО11 Север | D27: Скрылев А.В. | E27: Жукова А.И. | F27: 8. ПРОСПЕЦ_РФ | H27: 0.52941176 | I27: 0.76470588 | J27: =VLOOKUP(E27,'Эффективная коммуникация оценка'!$E$1:$P$297,12,0) -> 0.75 | K27: =VLOOKUP(E27,'навыки техники продаж оценка'!$E$2:$P$297,12,0) -> 0.75 | L27: 37.156761
A28: 251 | B28: Москва | C28: ПроСпец М12 Северо-Запад-Север | D28: Котельникова Е.Б. | E28: Веденина Т.Ю. | F28: 8. ПРОСПЕЦ_РФ | H28: 0.66176471 | I28: 0.70588235 | J28: =VLOOKUP(E28,'Эффективная коммуникация оценка'!$E$1:$P$297,12,0) -> 0.65 | K28: =VLOOKUP(E28,'навыки техники продаж оценка'!$E$2:$P$297,12,0) -> 0.66666667 | L28: 21.99842
A29: 7 | B29: Москва | C29: ПроРеспи МО6 Юго-Восток | D29: Давыдова Е.В. | E29: Сурова О.И. | F29: 8. ПРОРЕСПИ_РФ | I29: 0.38235294 | J29: =VLOOKUP(E29,'Эффективная коммуникация оценка'!$E$1:$P$297,12,0) -> 0.4 | K29: =VLOOKUP(E29,'навыки техники продаж оценка'!$E$2:$P$297,12,0) -> 0.25 | L29: 25
A30: 12 | B30: Москва | C30: ПроСпец МО3 Восток | D30: Давыдова Е.В. | E30: Николаева Е.А. | F30: 8. ПРОСПЕЦ_РФ | H30: 0.61764706 | I30: 0.70588235 | J30: =VLOOKUP(E30,'Эффективная коммуникация оценка'!$E$1:$P$297,12,0) -> 0.85 | K30: =VLOOKUP(E30,'навыки техники продаж оценка'!$E$2:$P$297,12,0) -> 0.66666667 | L30: 48.375
A31: 23 | B31: Москва | C31: ПроРеспи МО2 Восток | D31: Давыдова Е.В. | E31: Алешина Л.Г. | F31: 8. ПРОРЕСПИ_РФ | H31: 0.72058824 | I31: 0.64705882 | J31: =VLOOKUP(E31,'Эффективная коммуникация оценка'!$E$1:$P$297,12,0) -> 0.7 | K31: =VLOOKUP(E31,'навыки техники продаж оценка'!$E$2:$P$297,12,0) -> 0.66666667 | L31: 55.400572
A32: 28 | B32: Москва | C32: ПроРеспи МО8 Юг | D32: Скрылев А.В. | E32: Панкратов В.А. | F32: 8. ПРОРЕСПИ_РФ | H32: 0.70588235 | I32: 0.67647059 | J32: =VLOOKUP(E32,'Эффективная коммуникация оценка'!$E$1:$P$297,12,0) -> 0.7 | K32: =VLOOKUP(E32,'навыки техники продаж оценка'!$E$2:$P$297,12,0) -> 0.75 | L32: 23.8972
A33: 40 | B33: Москва | C33: ПроСпец МО4 Восток+Юго-Восток | D33: Давыдова Е.В. | E33: Прудникова Ю.С. | F33: 8. ПРОСПЕЦ_РФ | H33: 0.44117647 | I33: 0.72058824 | J33: =VLOOKUP(E33,'Эффективная коммуникация оценка'!$E$1:$P$297,12,0) -> 0.8 | K33: =VLOOKUP(E33,'навыки техники продаж оценка'!$E$2:$P$297,12,0) -> 0.66666667 | L33: 24.3125
A34: 44 | B34: Москва | C34: ПроРеспи МО5 Юго-Восток | D34: Давыдова Е.В. | E34: Шубин Я.А. | F34: 8. ПРОРЕСПИ_РФ | H34: 0.57352941 | I34: 0.61764706 | J34: =VLOOKUP(E34,'Эффективная коммуникация оценка'!$E$1:$P$297,12,0) -> 0.55 | K34: =VLOOKUP(E34,'навыки техники продаж оценка'!$E$2:$P$297,12,0) -> 0.58333333 | L34: 30.009407
A35: 52 | B35: Москва | C35: ПроСпец МО7 ЮГ | D35: Скрылев А.В. | E35: Туркина В.С. | F35: 8. ПРОСПЕЦ_РФ | H35: 0.52941176 | I35: 0.80882353 | J35: =VLOOKUP(E35,'Эффективная коммуникация оценка'!$E$1:$P$297,12,0) -> 0.85 | K35: =VLOOKUP(E35,'навыки техники продаж оценка'!$E$2:$P$297,12,0) -> 0.83333333 | L35: 40.432326
A36: 59 | B36: Москва | C36: ПроСпец МО5 Юго- и Северо-Восток | D36: Давыдова Е.В. | E36: Лесничая М.А. | F36: 8. ПРОСПЕЦ_РФ | H36: 0.36764706 | I36: 0.60294118 | J36: =VLOOKUP(E36,'Эффективная коммуникация оценка'!$E$1:$P$297,12,0) -> 0.6 | K36: =VLOOKUP(E36,'навыки техники продаж оценка'!$E$2:$P$297,12,0) -> 0.5 | L36: 27.02801
A37: 68 | B37: Москва | C37: ПроСпец МО9 Северо-Запад | D37: Скрылев А.В. | E37: Терзи Т.И. | F37: 8. ПРОСПЕЦ_РФ | H37: 0.55882353 | I37: 0.82352941 | J37: =VLOOKUP(E37,'Эффективная коммуникация оценка'!$E$1:$P$297,12,0) -> 0.85 | K37: =VLOOKUP(E37,'навыки техники продаж оценка'!$E$2:$P$297,12,0) -> 0.91666667 | L37: 51.156662
A38: 124 | B38: Москва | C38: ПроРеспи МО10 Запад | D38: Скрылев А.В. | E38: Борисенко Е.П. | F38: 8. ПРОРЕСПИ_РФ | H38: 0.60294118 | I38: 0.69117647 | J38: =VLOOKUP(E38,'Эффективная коммуникация оценка'!$E$1:$P$297,12,0) -> 0.7 | K38: =VLOOKUP(E38,'навыки техники продаж оценка'!$E$2:$P$297,12,0) -> 0.91666667 | L38: 58.633333
A39: 144 | B39: Москва | C39: ПроРеспи МО4 Восток | D39: Давыдова Е.В. | E39: Фиронова А.А. | F39: 8. ПРОРЕСПИ_РФ | H39: 0.44117647 | I39: 0.64705882 | J39: =VLOOKUP(E39,'Эффективная коммуникация оценка'!$E$1:$P$297,12,0) -> 0.6 | K39: =VLOOKUP(E39,'навыки техники продаж оценка'!$E$2:$P$297,12,0) -> 0.5 | L39: 38.090375
A40: 162 | B40: Москва | C40: ПроРеспи МО11 Северо-Запад | D40: Скрылев А.В. | E40: Осипова Ю.С. | F40: 8. ПРОРЕСПИ_РФ | H40: 0.61764706 | I40: 0.69117647 | J40: =VLOOKUP(E40,'Эффективная коммуникация оценка'!$E$1:$P$297,12,0) -> 0.75 | K40: =VLOOKUP(E40,'навыки техники продаж оценка'!$E$2:$P$297,12,0) -> 0.75 | L40: 23.034997
...

Sheet РАФАМИН_брики
B1: Регион ММХ | C1: Область | D1: Менеджер | E1: Сотрудник | F1: Эшелон | G1: Брик | H1: Оценка (мп.), % | I1: Оценка общая (рук.), % | J1: Оценка эффективности коммуникации (рук.), % | K1: Оценка навыки продаж (рук.), % | L1: Динамика региона
A2: 0 | B2: Москва | C2: ПроРеспи М4 Восток | D2: Мальцева А.А. | E2: Абазова А.С. | F2: 8. ПРОРЕСПИ_РФ | H2: 0.55882353 | I2: 0.55882353 | J2: =VLOOKUP(E2,'Эффективная коммуникация оценка'!$E$1:$P$297,12,0) -> 0.4 | K2: =VLOOKUP(E2,'навыки техники продаж оценка'!$E$2:$P$297,12,0) -> 0.58333333 | L2: -0.92165899
A3: 16 | B3: Москва | C3: ПроРеспи М10 Юго-Запад | D3: Кавунова И.Г. | E3: Антонов Д.А. | F3: 8. ПРОРЕСПИ_РФ | H3: 0.55882353 | I3: 0.64705882 | J3: =VLOOKUP(E3,'Эффективная коммуникация оценка'!$E$1:$P$297,12,0) -> 0.65 | K3: =VLOOKUP(E3,'навыки техники продаж оценка'!$E$2:$P$297,12,0) -> 0.58333333 | L3: -10.733591
A4: 21 | B4: Москва | C4: ПроРеспи М16 Север | D4: Котельникова Е.Б. | E4: Бодрова А.В. | F4: 8. ПРОРЕСПИ_РФ | H4: 0.72058824 | I4: 0.73529412 | J4: =VLOOKUP(E4,'Эффективная коммуникация оценка'!$E$1:$P$297,12,0) -> 0.65 | K4: =VLOOKUP(E4,'навыки техники продаж оценка'!$E$2:$P$297,12,0) -> 0.75 | L4: 31.108498
A5: 47 | B5: Москва | C5: ПроРеспи МО9 ТиНАО | D5: Скрылев А.В. | E5: Прищеп Л.П. | F5: 8. ПРОРЕСПИ_РФ | H5: 0.60294118 | I5: 0.75 | J5: =VLOOKUP(E5,'Эффективная коммуникация оценка'!$E$1:$P$297,12,0) -> 0.8 | K5: =VLOOKUP(E5,'навыки техники продаж оценка'!$E$2:$P$297,12,0) -> 0.66666667 | L5: 22.637238
A6: 60 | B6: Москва | C6: ПроРеспи М1 Восток | D6: Мальцева А.А. | E6: Афанасьева Ю.А. | F6: 8. ПРОРЕСПИ_РФ | H6: 0.52941176 | I6: 0.66176471 | J6: =VLOOKUP(E6,'Эффективная коммуникация оценка'!$E$1:$P$297,12,0) -> 0.7 | K6: =VLOOKUP(E6,'навыки техники продаж оценка'!$E$2:$P$297,12,0) -> 0.66666667 | L6: 26.521164
A7: 75 | B7: Москва | C7: ПроРеспи М14 Юг | D7: Кавунова И.Г. | E7: Семенова Т.Н. | F7: 8. ПРОРЕСПИ_РФ | H7: 0.52941176 | I7: 0.58823529 | J7: =VLOOKUP(E7,'Эффективная коммуникация оценка'!$E$1:$P$297,12,0) -> 0.6 | K7: =VLOOKUP(E7,'навыки техники продаж оценка'!$E$2:$P$297,12,0) -> 0.5 | L7: -17.442778
A8: 78 | B8: Москва | C8: ПроРеспи М11 Юго-Запад | D8: Кавунова И.Г. | E8: Разгуляева Т.А. | F8: 8. ПРОРЕСПИ_РФ | H8: 0.58823529 | I8: 0.64705882 | J8: =VLOOKUP(E8,'Эффективная коммуникация оценка'!$E$1:$P$297,12,0) -> 0.6 | K8: =VLOOKUP(E8,'навыки техники продаж оценка'!$E$2:$P$297,12,0) -> 0.58333333 | L8: -17.258883
A9: 86 | B9: Москва | C9: ПроРеспи М15 Север | D9: Котельникова Е.Б. | E9: Каминский Н.В. | F9: 8. ПРОРЕСПИ_РФ | H9: 0.5 | I9: 0.66176471 | J9: =VLOOKUP(E9,'Эффективная коммуникация оценка'!$E$1:$P$297,12,0) -> 0.55 | K9: =VLOOKUP(E9,'навыки техники продаж оценка'!$E$2:$P$297,12,0) -> 0.5 | L9: -15.962441
A10: 95 | B10: Москва | C10: ПроРеспи М2 Юго-Восток | D10: Мальцева А.А. | E10: Дмитраш А.В. | F10: 8. ПРОРЕСПИ_РФ | H10: 0.35294118 | I10: 0.54411765 | J10: =VLOOKUP(E10,'Эффективная коммуникация оценка'!$E$1:$P$297,12,0) -> 0.55 | K10: =VLOOKUP(E10,'навыки техники продаж оценка'!$E$2:$P$297,12,0) -> 0.58333333 | L10: -18.373151
A11: 99 | B11: Москва | C11: ПроСпец М5 Центр | D11: Мальцева А.А. | E11: Козырева Е.Н. | F11: 8. ПРОСПЕЦ_РФ | H11: 0.55882353 | I11: 0.52941176 | J11: =VLOOKUP(E11,'Эффективная коммуникация оценка'!$E$1:$P$297,12,0) -> 0.6 | K11: =VLOOKUP(E11,'навыки техники продаж оценка'!$E$2:$P$297,12,0) -> 0.5 | L11: 10.793494
A12: 100 | B12: Москва | C12: ПроРеспи М20 Северо-Восток | D12: Котельникова Е.Б. | E12: Кабатова И.А. | F12: 8. ПРОРЕСПИ_РФ | H12: 0.66176471 | I12: 0.69117647 | J12: =VLOOKUP(E12,'Эффективная коммуникация оценка'!$E$1:$P$297,12,0) -> 0.7 | K12: =VLOOKUP(E12,'навыки техники продаж оценка'!$E$2:$P$297,12,0) -> 0.75 | L12: 4.1237113
A13: 112 | B13: Москва | C13: ПроСпец М8 Юго-Восток | D13: Мальцева А.А. | E13: Кравцова А.С. | F13: 8. ПРОСПЕЦ_РФ | I13: 0.51470588 | J13: =VLOOKUP(E13,'Эффективная коммуникация оценка'!$E$1:$P$297,12,0) -> 0.55 | K13: =VLOOKUP(E13,'навыки техники продаж оценка'!$E$2:$P$297,12,0) -> 0.5 | L13: -22.37055
A14: 130 | B14: Москва | C14: ПроРеспи М7 Запад | D14: Кавунова И.Г. | E14: Иванова А.В. | F14: 8. ПРОРЕСПИ_РФ | H14: 0.54411765 | I14: 0.60294118 | J14: =VLOOKUP(E14,'Эффективная коммуникация оценка'!$E$1:$P$297,12,0) -> 0.65 | K14: =VLOOKUP(E14,'навыки техники продаж оценка'!$E$2:$P$297,12,0) -> 0.58333333 | L14: -9.0217942
A15: 134 | B15: Москва | C15: ПроСпец М6 Центр | D15: Мальцева А.А. | E15: Нефедова Э.С. | F15: 8. ПРОСПЕЦ_РФ | I15: 0.44117647 | J15: =VLOOKUP(E15,'Эффективная коммуникация оценка'!$E$1:$P$297,12,0) -> 0.4 | K15: =VLOOKUP(E15,'навыки техники продаж оценка'!$E$2:$P$297,12,0) -> 0.25 | L15: 13.458188
A16: 159 | B16: Москва | C16: ПроСпец М3 Юг | D16: Кавунова И.Г. | E16: Стрельникова М.Ю. | F16: 8. ПРОСПЕЦ_РФ | I16: 0.73529412 | J16: =VLOOKUP(E16,'Эффективная коммуникация оценка'!$E$1:$P$297,12,0) -> 0.7 | K16: =VLOOKUP(E16,'навыки техники продаж оценка'!$E$2:$P$297,12,0) -> 0.75 | L16: -10.719132
A17: 168 | B17: Москва | C17: ПроРеспи М3 Восток | D17: Котельникова Е.Б. | E17: Каманова А.А. | F17: 8. ПРОРЕСПИ_РФ | H17: 0.54411765 | I17: 0.64705882 | J17: =VLOOKUP(E17,'Эффективная коммуникация оценка'!$E$1:$P$297,12,0) -> 0.65 | K17: =VLOOKUP(E17,'навыки техники продаж оценка'!$E$2:$P$297,12,0) -> 0.5 | L17: 2.5290499
A18: 169 | B18: Москва | C18: ПроСпец М11 Северо-Восток | D18: Котельникова Е.Б. | E18: Егорова Т.И. | F18: 8. ПРОСПЕЦ_РФ | H18: 0.48529412 | I18: 0.67647059 | J18: =VLOOKUP(E18,'Эффективная коммуникация оценка'!$E$1:$P$297,12,0) -> 0.65 | K18: =VLOOKUP(E18,'навыки техники продаж оценка'!$E$2:$P$297,12,0) -> 0.58333333 | L18: -5.78125
A19: 190 | B19: Москва | C19: ПроСпец МО8 ТиНАО | D19: Скрылев А.В. | E19: Гарматин В.О. | F19: 8. ПРОСПЕЦ_РФ | I19: 0.5 | J19: =VLOOKUP(E19,'Эффективная коммуникация оценка'!$E$1:$P$297,12,0) -> 0.4 | K19: =VLOOKUP(E19,'навыки техники продаж оценка'!$E$2:$P$297,12,0) -> 0.58333333 | L19: 22.637238
A20: 202 | B20: Москва | C20: ПроРеспи М17 Северо-Запад | D20: Котельникова Е.Б. | E20: Грязнова О.А. | F20: 8. ПРОРЕСПИ_РФ | H20: 0.69117647 | I20: 0.69117647 | J20: =VLOOKUP(E20,'Эффективная коммуникация оценка'!$E$1:$P$297,12,0) -> 0.6 | K20: =VLOOKUP(E20,'навыки техники продаж оценка'!$E$2:$P$297,12,0) -> 0.58333333 | L20: -12.935954
A21: 210 | B21: Москва | C21: ПроРеспи М12 Юг | D21: Кавунова И.Г. | E21: Селезнева Ю.В. | F21: 8. ПРОРЕСПИ_РФ | H21: 0.57352941 | I21: 0.55882353 | J21: =VLOOKUP(E21,'Эффективная коммуникация оценка'!$E$1:$P$297,12,0) -> 0.55 | K21: =VLOOKUP(E21,'навыки техники продаж оценка'!$E$2:$P$297,12,0) -> 0.66666667 | L21: 5.7471264
A22: 212 | B22: Москва | C22: ПроРеспи М5 Центр | D22: Мальцева А.А. | E22: Юрова А.В. | F22: 8. ПРОРЕСПИ_РФ | H22: 0.5 | I22: 0.60294118 | J22: =VLOOKUP(E22,'Эффективная коммуникация оценка'!$E$1:$P$297,12,0) -> 0.6 | K22: =VLOOKUP(E22,'навыки техники продаж оценка'!$E$2:$P$297,12,0) -> 0.58333333 | L22: 13.458188
A23: 218 | B23: Москва | C23: ПроСпец М10 Восток-Северо-Восток | D23: Котельникова Е.Б. | E23: Касимова М.М. | F23: 8. ПРОСПЕЦ_РФ | H23: 0.75 | I23: 0.63235294 | J23: =VLOOKUP(E23,'Эффективная коммуникация оценка'!$E$1:$P$297,12,0) -> 0.8 | K23: =VLOOKUP(E23,'навыки техники продаж оценка'!$E$2:$P$297,12,0) -> 0.58333333 | L23: -5.5555556
A24: 219 | B24: Москва | C24: ПроРеспи М6 Центр | D24: Мальцева А.А. | E24: Шебалкова Т.Н. | F24: 8. ПРОРЕСПИ_РФ | H24: 0.60294118 | I24: 0.83823529 | J24: =VLOOKUP(E24,'Эффективная коммуникация оценка'!$E$1:$P$297,12,0) -> 0.85 | K24: =VLOOKUP(E24,'навыки техники продаж оценка'!$E$2:$P$297,12,0) -> 0.91666667 | L24: 10.793494
A25: 234 | B25: Москва | C25: ПроСпец М7 Восток | D25: Мальцева А.А. | E25: Сагиндыкова Д.А. | F25: 8. ПРОСПЕЦ_РФ | H25: 0.42647059 | I25: 0.58823529 | J25: =VLOOKUP(E25,'Эффективная коммуникация оценка'!$E$1:$P$297,12,0) -> 0.55 | K25: =VLOOKUP(E25,'навыки техники продаж оценка'!$E$2:$P$297,12,0) -> 0.58333333 | L25: -0.16319869
A26: 236 | B26: Москва | C26: ПроСпец М9 Юго-Восток-Юг | D26: Мальцева А.А. | E26: Наумова А.А. | F26: 8. ПРОСПЕЦ_РФ | I26: 0.69117647 | J26: =VLOOKUP(E26,'Эффективная коммуникация оценка'!$E$1:$P$297,12,0) -> 0.85 | K26: =VLOOKUP(E26,'навыки техники продаж оценка'!$E$2:$P$297,12,0) -> 0.58333333 | L26: 14.285714
A27: 240 | B27: Москва | C27: ПроСпец МО11 Север | D27: Скрылев А.В. | E27: Жукова А.И. | F27: 8. ПРОСПЕЦ_РФ | H27: 0.52941176 | I27: 0.76470588 | J27: =VLOOKUP(E27,'Эффективная коммуникация оценка'!$E$1:$P$297,12,0) -> 0.75 | K27: =VLOOKUP(E27,'навыки техники продаж оценка'!$E$2:$P$297,12,0) -> 0.75 | L27: -13.966707
A28: 251 | B28: Москва | C28: ПроСпец М12 Северо-Запад-Север | D28: Котельникова Е.Б. | E28: Веденина Т.Ю. | F28: 8. ПРОСПЕЦ_РФ | H28: 0.66176471 | I28: 0.70588235 | J28: =VLOOKUP(E28,'Эффективная коммуникация оценка'!$E$1:$P$297,12,0) -> 0.65 | K28: =VLOOKUP(E28,'навыки техники продаж оценка'!$E$2:$P$297,12,0) -> 0.66666667 | L28: -2.5479616
A29: 7 | B29: Москва | C29: ПроРеспи МО6 Юго-Восток | D29: Давыдова Е.В. | E29: Сурова О.И. | F29: 8. ПРОРЕСПИ_РФ | I29: 0.38235294 | J29: =VLOOKUP(E29,'Эффективная коммуникация оценка'!$E$1:$P$297,12,0) -> 0.4 | K29: =VLOOKUP(E29,'навыки техники продаж оценка'!$E$2:$P$297,12,0) -> 0.25 | L29: 18.913271
A30: 12 | B30: Москва | C30: ПроСпец МО3 Восток | D30: Давыдова Е.В. | E30: Николаева Е.А. | F30: 8. ПРОСПЕЦ_РФ | H30: 0.61764706 | I30: 0.70588235 | J30: =VLOOKUP(E30,'Эффективная коммуникация оценка'!$E$1:$P$297,12,0) -> 0.85 | K30: =VLOOKUP(E30,'навыки техники продаж оценка'!$E$2:$P$297,12,0) -> 0.66666667 | L30: 13.657771
A31: 23 | B31: Москва | C31: ПроРеспи МО2 Восток | D31: Давыдова Е.В. | E31: Алешина Л.Г. | F31: 8. ПРОРЕСПИ_РФ | H31: 0.72058824 | I31: 0.64705882 | J31: =VLOOKUP(E31,'Эффективная коммуникация оценка'!$E$1:$P$297,12,0) -> 0.7 | K31: =VLOOKUP(E31,'навыки техники продаж оценка'!$E$2:$P$297,12,0) -> 0.66666667 | L31: 1.5097691
A32: 28 | B32: Москва | C32: ПроРеспи МО8 Юг | D32: Скрылев А.В. | E32: Панкратов В.А. | F32: 8. ПРОРЕСПИ_РФ | H32: 0.70588235 | I32: 0.67647059 | J32: =VLOOKUP(E32,'Эффективная коммуникация оценка'!$E$1:$P$297,12,0) -> 0.7 | K32: =VLOOKUP(E32,'навыки техники продаж оценка'!$E$2:$P$297,12,0) -> 0.75 | L32: -14.700704
A33: 40 | B33: Москва | C33: ПроСпец МО4 Восток-Юго-Восток | D33: Давыдова Е.В. | E33: Прудникова Ю.С. | F33: 8. ПРОСПЕЦ_РФ | H33: 0.44117647 | I33: 0.72058824 | J33: =VLOOKUP(E33,'Эффективная коммуникация оценка'!$E$1:$P$297,12,0) -> 0.8 | K33: =VLOOKUP(E33,'навыки техники продаж оценка'!$E$2:$P$297,12,0) -> 0.66666667 | L33: 28.681319
A34: 44 | B34: Москва | C34: ПроРеспи МО5 Юго-Восток | D34: Давыдова Е.В. | E34: Шубин Я.А. | F34: 8. ПРОРЕСПИ_РФ | H34: 0.57352941 | I34: 0.61764706 | J34: =VLOOKUP(E34,'Эффективная коммуникация оценка'!$E$1:$P$297,12,0) -> 0.55 | K34: =VLOOKUP(E34,'навыки техники продаж оценка'!$E$2:$P$297,12,0) -> 0.58333333 | L34: 30.02594
A35: 52 | B35: Москва | C35: ПроСпец МО7 ЮГ | D35: Скрылев А.В. | E35: Туркина В.С. | F35: 8. ПРОСПЕЦ_РФ | H35: 0.52941176 | I35: 0.80882353 | J35: =VLOOKUP(E35,'Эффективная коммуникация оценка'!$E$1:$P$297,12,0) -> 0.85 | K35: =VLOOKUP(E35,'навыки техники продаж оценка'!$E$2:$P$297,12,0) -> 0.83333333 | L35: -8.3139805
A36: 59 | B36: Москва | C36: ПроСпец МО5 Юго- и Северо-Восток | D36: Давыдова Е.В. | E36: Лесничая М.А. | F36: 8. ПРОСПЕЦ_РФ | H36: 0.36764706 | I36: 0.60294118 | J36: =VLOOKUP(E36,'Эффективная коммуникация оценка'!$E$1:$P$297,12,0) -> 0.6 | K36: =VLOOKUP(E36,'навыки техники продаж оценка'!$E$2:$P$297,12,0) -> 0.5 | L36: 26.176471
A37: 68 | B37: Москва | C37: ПроСпец МО9 Северо-Запад | D37: Скрылев А.В. | E37: Терзи Т.И. | F37: 8. ПРОСПЕЦ_РФ | H37: 0.55882353 | I37: 0.82352941 | J37: =VLOOKUP(E37,'Эффективная коммуникация оценка'!$E$1:$P$297,12,0) -> 0.85 | K37: =VLOOKUP(E37,'навыки техники продаж оценка'!$E$2:$P$297,12,0) -> 0.91666667 | L37: 29.814433
A38: 124 | B38: Москва | C38: ПроРеспи МО10 Запад | D38: Скрылев А.В. | E38: Борисенко Е.П. | F38: 8. ПРОРЕСПИ_РФ | H38: 0.60294118 | I38: 0.69117647 | J38: =VLOOKUP(E38,'Эффективная коммуникация оценка'!$E$1:$P$297,12,0) -> 0.7 | K38: =VLOOKUP(E38,'навыки техники продаж оценка'!$E$2:$P$297,12,0) -> 0.91666667 | L38: 30.345711
A39: 144 | B39: Москва | C39: ПроРеспи МО4 Восток | D39: Давыдова Е.В. | E39: Фиронова А.А. | F39: 8. ПРОРЕСПИ_РФ | H39: 0.44117647 | I39: 0.64705882 | J39: =VLOOKUP(E39,'Эффективная коммуникация оценка'!$E$1:$P$297,12,0) -> 0.6 | K39: =VLOOKUP(E39,'навыки техники продаж оценка'!$E$2:$P$297,12,0) -> 0.5 | L39: 8.541915
A40: 162 | B40: Москва | C40: ПроРеспи МО11 Северо-Запад | D40: Скрылев А.В. | E40: Осипова Ю.С. | F40: 8. ПРОРЕСПИ_РФ | H40: 0.61764706 | I40: 0.69117647 | J40: =VLOOKUP(E40,'Эффективная коммуникация оценка'!$E$1:$P$297,12,0) -> 0.75 | K40: =VLOOKUP(E40,'навыки техники продаж оценка'!$E$2:$P$297,12,0) -> 0.75 | L40: 16.420308
...

Sheet РАФАМИН_регионы
B1: Регион ММХ | C1: Область | D1: Менеджер | E1: Сотрудник | F1: Эшелон | H1: Оценка (мп.), % | I1: Оценка общая (рук.), % | J1: Оценка эффективности коммуникации (рук.), % | K1: Оценка навыки продаж (рук.), % | L1: Выполнение плана | M1: Динамика региона
A2: 32 | B2: Сибирь | C2: Алтайский край | D2: Миронова О.В. | E2: Чуданов В.Е. | F2: 8. ПРОРЕСПИ_РФ | H2: 0.54411765 | I2: 0.33823529 | J2: =VLOOKUP(E2,'Эффективная коммуникация оценка'!$E$1:$P$297,12,0) -> 0.35 | K2: =VLOOKUP(E2,'навыки техники продаж оценка'!$E$2:$P$297,12,0) -> 0.33333333 | L2: 72.708963 | M2: -9.0598291 | P2: Названия строк | Q2: Среднее по полю Оценка общая (рук.), % | R2: Среднее по полю Выполнение плана | S2: Среднее по полю Динамика региона
A3: 156 | B3: Сибирь | C3: Алтайский край | D3: Миронова О.В. | E3: Егудина М.А. | F3: 8. ПРОСПЕЦ_РФ | I3: 0.58823529 | J3: =VLOOKUP(E3,'Эффективная коммуникация оценка'!$E$1:$P$297,12,0) -> 0.6 | K3: =VLOOKUP(E3,'навыки техники продаж оценка'!$E$2:$P$297,12,0) -> 0.58333333 | L3: 72.708963 | M3: -9.0598291 | P3: Алтайский край | Q3: 0.53676471 | R3: 72.708963 | S3: -9.0598291
A4: 248 | B4: Сибирь | C4: Алтайский край | D4: Миронова О.В. | E4: Червова О.В. | F4: 8. ПРОРЕСПИ_РФ | H4: 0.55882353 | I4: 0.63235294 | J4: =VLOOKUP(E4,'Эффективная коммуникация оценка'!$E$1:$P$297,12,0) -> 0.65 | K4: =VLOOKUP(E4,'навыки техники продаж оценка'!$E$2:$P$297,12,0) -> 0.5 | L4: 72.708963 | M4: -9.0598291 | P4: Архангельская обл | Q4: 0.59558824 | R4: 96.717541 | S4: 16.759213
A5: 255 | B5: Сибирь | C5: Алтайский край | D5: Миронова О.В. | E5: Петрова Е.А. | F5: 8. ПРОСПЕЦ_РФ | H5: 0.63235294 | I5: 0.58823529 | J5: =VLOOKUP(E5,'Эффективная коммуникация оценка'!$E$1:$P$297,12,0) -> 0.7 | K5: =VLOOKUP(E5,'навыки техники продаж оценка'!$E$2:$P$297,12,0) -> 0.58333333 | L5: 72.708963 | M5: -9.0598291 | P5: Астраханская обл | Q5: 0.72058824 | R5: 100.84732 | S5: 22.505938
A6: 151 | B6: Северо-Запад | C6: Архангельская обл | D6: Евсеева М.Ю. | E6: Фролова Н.Г. | F6: 8. ПРОСПЕЦ_РФ | H6: 0.5 | I6: 0.55882353 | J6: =VLOOKUP(E6,'Эффективная коммуникация оценка'!$E$1:$P$297,12,0) -> 0.6 | K6: =VLOOKUP(E6,'навыки техники продаж оценка'!$E$2:$P$297,12,0) -> 0.5 | L6: 96.717541 | M6: 16.759213 | P6: Башкортостан Респ | Q6: 0.65257353 | R6: 75.851943 | S6: -7.7609791
A7: 188 | B7: Северо-Запад | C7: Архангельская обл | D7: Евсеева М.Ю. | E7: Данилюк Н.В. | F7: 8. ПРОРЕСПИ_РФ | H7: 0.52941176 | I7: 0.63235294 | J7: =VLOOKUP(E7,'Эффективная коммуникация оценка'!$E$1:$P$297,12,0) -> 0.75 | K7: =VLOOKUP(E7,'навыки техники продаж оценка'!$E$2:$P$297,12,0) -> 0.66666667 | L7: 96.717541 | M7: 16.759213 | P7: Белгородская обл | Q7: 0.69117647 | R7: 110.58522 | S7: 71.103896
A8: 163 | B8: Юг | C8: Астраханская обл | D8: Петровская О.В. | E8: Хайрлиева Г.С. | F8: 8. ПРОСПЕЦ_РФ | H8: 0.64705882 | I8: 0.76470588 | J8: =VLOOKUP(E8,'Эффективная коммуникация оценка'!$E$1:$P$297,12,0) -> 0.8 | K8: =VLOOKUP(E8,'навыки техники продаж оценка'!$E$2:$P$297,12,0) -> 0.75 | L8: 100.84732 | M8: 22.505938 | P8: Брянская обл | Q8: 0.75735294 | R8: 108.54016 | S8: 32.934418
A9: 221 | B9: Юг | C9: Астраханская обл | D9: Петровская О.В. | E9: Вострикова З.Ф. | F9: 8. ПРОРЕСПИ_РФ | H9: 0.51470588 | I9: 0.67647059 | J9: =VLOOKUP(E9,'Эффективная коммуникация оценка'!$E$1:$P$297,12,0) -> 0.7 | K9: =VLOOKUP(E9,'навыки техники продаж оценка'!$E$2:$P$297,12,0) -> 0.58333333 | L9: 100.84732 | M9: 22.505938 | P9: Бурятия Респ | Q9: 0.77941176 | R9: 86.757009 | S9: -3.1305437
A10: 13 | B10: Урал | C10: Башкортостан Респ | D10: Митяшева О.Б. | E10: Егорова И.В. | F10: 8. ПРОСПЕЦ_РФ | H10: 0.61764706 | I10: 0.80882353 | J10: =VLOOKUP(E10,'Эффективная коммуникация оценка'!$E$1:$P$297,12,0) -> 0.85 | K10: =VLOOKUP(E10,'навыки техники продаж оценка'!$E$2:$P$297,12,0) -> 0.66666667 | L10: 75.851943 | M10: -7.7609791 | P10: Владимирская обл | Q10: 0.65441176 | R10: 68.977556 | S10: -7.1500504
A11: 15 | B11: Урал | C11: Башкортостан Респ | D11: Митяшева О.Б. | E11: Якушева А.А. | F11: 8. ПРОСПЕЦ_РФ | H11: 0.45588235 | I11: 0.63235294 | J11: =VLOOKUP(E11,'Эффективная коммуникация оценка'!$E$1:$P$297,12,0) -> 0.7 | K11: =VLOOKUP(E11,'навыки техники продаж оценка'!$E$2:$P$297,12,0) -> 0.58333333 | L11: 75.851943 | M11: -7.7609791 | P11: Волгоградская обл | Q11: 0.75882353 | R11: 93.315559 | S11: 18.629706
A12: 31 | B12: Урал | C12: Башкортостан Респ | D12: Машукова О.М. | E12: Ваняшкина Е.С. | F12: 8. ПРОРЕСПИ_РФ | H12: 0.38235294 | I12: 0.38235294 | J12: =VLOOKUP(E12,'Эффективная коммуникация оценка'!$E$1:$P$297,12,0) -> 0.45 | K12: =VLOOKUP(E12,'навыки техники продаж оценка'!$E$2:$P$297,12,0) -> 0.33333333 | L12: 75.851943 | M12: -7.7609791 | P12: Вологодская обл | Q12: 0.72058824 | R12: 96.034081 | S12: 41.229117
A13: 49 | B13: Урал | C13: Башкортостан Респ | D13: Машукова О.М. | E13: Курбангулова Г.Ю. | F13: 8. ПРОРЕСПИ_РФ | H13: 0.52941176 | I13: 0.60294118 | J13: =VLOOKUP(E13,'Эффективная коммуникация оценка'!$E$1:$P$297,12,0) -> 0.75 | K13: =VLOOKUP(E13,'навыки техники продаж оценка'!$E$2:$P$297,12,0) -> 0.58333333 | L13: 75.851943 | M13: -7.7609791 | P13: Воронежская обл | Q13: 0.67941176 | R13: 57.940229 | S13: 8.4899191
A14: 132 | B14: Урал | C14: Башкортостан Респ | D14: Митяшева О.Б. | E14: Зегер Е.О. | F14: 8. ПРОСПЕЦ_РФ | H14: 0.69117647 | I14: 0.86764706 | J14: =VLOOKUP(E14,'Эффективная коммуникация оценка'!$E$1:$P$297,12,0) -> 0.9 | K14: =VLOOKUP(E14,'навыки техники продаж оценка'!$E$2:$P$297,12,0) -> 0.66666667 | L14: 75.851943 | M14: -7.7609791 | P14: Забайкальский край | Q14: 0.85294118 | R14: 105.80989 | S14: 36.572438
A15: 164 | B15: Урал | C15: Башкортостан Респ | D15: Машукова О.М. | E15: Шастова И.С. | F15: 8. ПРОРЕСПИ_РФ | H15: 0.67647059 | I15: 0.83823529 | J15: =VLOOKUP(E15,'Эффективная коммуникация оценка'!$E$1:$P$297,12,0) -> 0.95 | K15: =VLOOKUP(E15,'навыки техники продаж оценка'!$E$2:$P$297,12,0) -> 0.75 | L15: 75.851943 | M15: -7.7609791 | P15: Ивановская обл | Q15: 0.67647059 | R15: 77.792916 | S15: 37.259615
... A63: 102 | B63: Юг | C63: Краснодарский край | D63: Туксина В.Н. | E63: Хагурова М.А. | F63: 8. ПРОРЕСПИ_РФ | H63: 0.67647059 | I63: 0.54411765 | J63: =VLOOKUP(E63,'Эффективная коммуникация оценка'!$E$1:$P$297,12,0) -> 0.6 | K63: =VLOOKUP(E63,'навыки техники продаж оценка'!$E$2:$P$297,12,0) -> 0.5 | L63: 76.738154 | M63: -5.0409151 | P63: Общий итог | Q63: 0.67241198 | R63: 83.259175 | S63: 6.2113621
A64: 114 | B64: Юг | C64: Краснодарский край | D64: Туксина В.Н. | E64: Грекова Л.Л. | F64: 8. ПРОСПЕЦ_РФ | H64: 0.72058824 | I64: 0.77941176 | J64: =VLOOKUP(E64,'Эффективная коммуникация оценка'!$E$1:$P$297,12,0) -> 0.85 | K64: =VLOOKUP(E64,'навыки техники продаж оценка'!$E$2:$P$297,12,0) -> 0.66666667 | L64: 76.738154 | M64: -5.0409151
A65: 127 | B65: Юг | C65: Краснодарский край | D65: Туксина В.Н. | E65: Федоренко Е.В. | F65: 8. ПРОРЕСПИ_РФ | H65: 0.61764706 | I65: 0.67647059 | J65: =VLOOKUP(E65,'Эффективная коммуникация оценка'!$E$1:$P$297,12,0) -> 0.7 | K65: =VLOOKUP(E65,'навыки техники продаж оценка'!$E$2:$P$297,12,0) -> 0.75 | L65: 76.738154 | M65: -5.0409151
A66: 199 | B66: Юг | C66: Краснодарский край | D66: Туксина В.Н. | E66: Воронина Ю.Ю. | F66: 8. ПРОСПЕЦ_РФ | H66: 0.55882353 | I66: 0.83823529 | J66: =VLOOKUP(E66,'Эффективная коммуникация оценка'!$E$1:$P$297,12,0) -> 0.9 | K66: =VLOOKUP(E66,'навыки техники продаж оценка'!$E$2:$P$297,12,0) -> 0.75 | L66: 76.738154 | M66: -5.0409151
A67: 235 | B67: Юг | C67: Краснодарский край | D67: Туксина В.Н. | E67: Китаева О.Е. | F67: 8. ПРОСПЕЦ_РФ | H67: 0.48529412 | I67: 0.58823529 | J67: =VLOOKUP(E67,'Эффективная коммуникация оценка'!$E$1:$P$297,12,0) -> 0.6 | K67: =VLOOKUP(E67,'навыки техники продаж оценка'!$E$2:$P$297,12,0) -> 0.5 | L67: 76.738154 | M67: -5.0409151
A68: 17 | B68: Сибирь | C68: Красноярский край | D68: Рассказчикова М.В. | E68: Шваб Н.А. | F68: 8. ПРОСПЕЦ_РФ | H68: 0.64705882 | I68: 0.80882353 | J68: =VLOOKUP(E68,'Эффективная коммуникация оценка'!$E$1:$P$297,12,0) -> 0.95 | K68: =VLOOKUP(E68,'навыки техники продаж оценка'!$E$2:$P$297,12,0) -> 0.83333333 | L68: 72.473868 | M68: -20.277224
A69: 170 | B69: Сибирь | C69: Красноярский край | D69: Рассказчикова М.В. | E69: Ворычева А.А. | F69: 8. ПРОРЕСПИ_РФ | H69: 0.63235294 | I69: 0.82352941 | J69: =VLOOKUP(E69,'Эффективная коммуникация оценка'!$E$1:$P$297,12,0) -> 0.85 | K69: =VLOOKUP(E69,'навыки техники продаж оценка'!$E$2:$P$297,12,0) -> 0.75 | L69: 72.473868 | M69: -20.277224
A70: 175 | B70: Сибирь | C70: Красноярский край | D70: Рассказчикова М.В. | E70: Баженова Л.Ф. | F70: 8. ПРОСПЕЦ_РФ | H70: 0.60294118 | I70: 0.73529412 | J70: =VLOOKUP(E70,'Эффективная коммуникация оценка'!$E$1:$P$297,12,0) -> 0.65 | K70: =VLOOKUP(E70,'навыки техники продаж оценка'!$E$2:$P$297,12,0) -> 0.75 | L70: 72.473868 | M70: -20.277224
A71: 268 | B71: Сибирь | C71: Красноярский край | D71: Рассказчикова М.В. | E71: Песегова С.В. | F71: 8. ПРОРЕСПИ_РФ | H71: 0.47058824 | I71: 0.64705882 | J71: =VLOOKUP(E71,'Эффективная коммуникация оценка'!$E$1:$P$297,12,0) -> 0.7 | K71: =VLOOKUP(E71,'навыки техники продаж оценка'!$E$2:$P$297,12,0) -> 0.75 | L71: 72.473868 | M71: -20.277224
A72: 56 | B72: Юг | C72: Крым Респ | D72: Туксина В.Н. | E72: Машталяр С.В. | F72: 8. ПРОРЕСПИ_РФ | H72: 0.55882353 | I72: 0.58823529 | J72: =VLOOKUP(E72,'Эффективная коммуникация оценка'!$E$1:$P$297,12,0) -> 0.55 | K72: =VLOOKUP(E72,'навыки техники продаж оценка'!$E$2:$P$297,12,0) -> 0.41666667 | L72: 86.371111 | M72: 4.3219194
A73: 105 | B73: Юг | C73: Крым Респ | D73: Туксина В.Н. | E73: Лотник Л.В. | F73: 8. ПРОСПЕЦ_РФ | H73: 0.72058824 | I73: 0.79411765 | J73: =VLOOKUP(E73,'Эффективная коммуникация оценка'!$E$1:$P$297,12,0) -> 0.8 | K73: =VLOOKUP(E73,'навыки техники продаж оценка'!$E$2:$P$297,12,0) -> 0.75 | L73: 86.371111 | M73: 4.3219194
A74: 250 | B74: Юг | C74: Крым Респ | D74: Туксина В.Н. | E74: Бешевли Л.И. | F74: 8. ПРОСПЕЦ_РФ | H74: 0.70588235 | I74: 0.92647059 | J74: =VLOOKUP(E74,'Эффективная коммуникация оценка'!$E$1:$P$297,12,0) -> 0.95 | K74: =VLOOKUP(E74,'навыки техники продаж оценка'!$E$2:$P$297,12,0) -> 1 | L74: 86.371111 | M74: 4.3219194
A75: 259 | B75: Юг | C75: Крым Респ | D75: Туксина В.Н. | E75: Зырянова Н.В. | F75: 8. ПРОРЕСПИ_РФ | H75: 0.67647059 | I75: 0.66176471 | J75: =VLOOKUP(E75,'Эффективная коммуникация оценка'!$E$1:$P$297,12,0) -> 0.65 | K75: =VLOOKUP(E75,'навыки техники продаж оценка'!$E$2:$P$297,12,0) -> 0.58333333 | L75: 86.371111 | M75: 4.3219194
... A92: 100 | B92: Москва | C92: Москва г | D92: Котельникова Е.Б. | E92: Кабатова И.А. | F92: 8. ПРОРЕСПИ_РФ | H92: 0.66176471 | I92: 0.69117647 | J92: =VLOOKUP(E92,'Эффективная коммуникация оценка'!$E$1:$P$297,12,0) -> 0.7 | K92: =VLOOKUP(E92,'навыки техники продаж оценка'!$E$2:$P$297,12,0) -> 0.75 | L92: 70.780292 | M92: -1.5794491
A93: 112 | B93: Москва | C93: Москва г | D93: Мальцева А.А. | E93: Кравцова А.С. | F93: 8. ПРОСПЕЦ_РФ | I93: 0.51470588 | J93: =VLOOKUP(E93,'Эффективная коммуникация оценка'!$E$1:$P$297,12,0) -> 0.55 | K93: =VLOOKUP(E93,'навыки техники продаж оценка'!$E$2:$P$297,12,0) -> 0.5 | L93: 70.780292 | M93: -1.5794491
A94: 130 | B94: Москва | C94: Москва г | D94: Кавунова И.Г. | E94: Иванова А.В. | F94: 8. ПРОРЕСПИ_РФ | H94: 0.54411765 | I94: 0.60294118 | J94: =VLOOKUP(E94,'Эффективная коммуникация оценка'!$E$1:$P$297,12,0) -> 0.65 | K94: =VLOOKUP(E94,'навыки техники продаж оценка'!$E$2:$P$297,12,0) -> 0.58333333 | L94: 70.780292 | M94: -1.5794491
A95: 134 | B95: Москва | C95: Москва г | D95: Мальцева А.А. | E95: Нефедова Э.С. | F95: 8. ПРОСПЕЦ_РФ | I95: 0.44117647 | J95: =VLOOKUP(E95,'Эффективная коммуникация оценка'!$E$1:$P$297,12,0) -> 0.4 | K95: =VLOOKUP(E95,'навыки техники продаж оценка'!$E$2:$P$297,12,0) -> 0.25 | L95: 70.780292 | M95: -1.5794491
A96: 159 | B96: Москва | C96: Москва г | D96: Кавунова И.Г. | E96: Стрельникова М.Ю. | F96: 8. ПРОСПЕЦ_РФ | I96: 0.73529412 | J96: =VLOOKUP(E96,'Эффективная коммуникация оценка'!$E$1:$P$297,12,0) -> 0.7 | K96: =VLOOKUP(E96,'навыки техники продаж оценка'!$E$2:$P$297,12,0) -> 0.75 | L96: 70.780292 | M96: -1.5794491
A97: 168 | B97: Москва | C97: Москва г | D97: Котельникова Е.Б. | E97: Каманова А.А. | F97: 8. ПРОРЕСПИ_РФ | H97: 0.54411765 | I97: 0.64705882 | J97: =VLOOKUP(E97,'Эффективная коммуникация оценка'!$E$1:$P$297,12,0) -> 0.65 | K97: =VLOOKUP(E97,'навыки техники продаж оценка'!$E$2:$P$297,12,0) -> 0.5 | L97: 70.780292 | M97: -1.5794491
A98: 169 | B98: Москва | C98: Москва г | D98: Котельникова Е.Б. | E98: Егорова Т.И. | F98: 8. ПРОСПЕЦ_РФ | H98: 0.48529412 | I98: 0.67647059 | J98: =VLOOKUP(E98,'Эффективная коммуникация оценка'!$E$1:$P$297,12,0) -> 0.65 | K98: =VLOOKUP(E98,'навыки техники продаж оценка'!$E$2:$P$297,12,0) -> 0.58333333 | L98: 70.780292 | M98: -1.5794491
A99: 190 | B99: Москва | C99: Москва г | D99: Скрылев А.В. | E99: Гарматин В.О. | F99: 8. ПРОСПЕЦ_РФ | I99: 0.5 | J99: =VLOOKUP(E99,'Эффективная коммуникация оценка'!$E$1:$P$297,12,0) -> 0.4 | K99: =VLOOKUP(E99,'навыки техники продаж оценка'!$E$2:$P$297,12,0) -> 0.58333333 | L99: 70.780292 | M99: -1.5794491
A100: 202 | B100: Москва | C100: Москва г | D100: Котельникова Е.Б. | E100: Грязнова О.А. | F100: 8. ПРОРЕСПИ_РФ | H100: 0.69117647 | I100: 0.69117647 | J100: =VLOOKUP(E100,'Эффективная коммуникация оценка'!$E$1:$P$297,12,0) -> 0.6 | K100: =VLOOKUP(E100,'навыки техники продаж оценка'!$E$2:$P$297,12,0) -> 0.58333333 | L100: 70.780292 | M100: -1.5794491
A101: 210 | B101: Москва | C101: Москва г | D101: Кавунова И.Г. | E101: Селезнева Ю.В. | F101: 8. ПРОРЕСПИ_РФ | H101: 0.57352941 | I101: 0.55882353 | J101: =VLOOKUP(E101,'Эффективная коммуникация оценка'!$E$1:$P$297,12,0) -> 0.55 | K101: =VLOOKUP(E101,'навыки техники продаж оценка'!$E$2:$P$297,12,0) -> 0.66666667 | L101: 70.780292 | M101: -1.5794491
A102: 212 | B102: Москва | C102: Москва г | D102: Мальцева А.А. | E102: Юрова А.В. | F102: 8. ПРОРЕСПИ_РФ | H102: 0.5 | I102: 0.60294118 | J102: =VLOOKUP(E102,'Эффективная коммуникация оценка'!$E$1:$P$297,12,0) -> 0.6 | K102: =VLOOKUP(E102,'навыки техники продаж оценка'!$E$2:$P$297,12,0) -> 0.58333333 | L102: 70.780292 | M102: -1.5794491
A103: 218 | B103: Москва | C103: Москва г | D103: Котельникова Е.Б. | E103: Касимова М.М. | F103: 8. ПРОСПЕЦ_РФ | H103: 0.75 | I103: 0.63235294 | J103: =VLOOKUP(E103,'Эффективная коммуникация оценка'!$E$1:$P$297,12,0) -> 0.8 | K103: =VLOOKUP(E103,'навыки техники продаж оценка'!$E$2:$P$297,12,0) -> 0.58333333 | L103: 70.780292 | M103: -1.5794491
...

Sheet РАФАМИН_брикирегионы
B1: Регион ММХ | C1: Область | D1: Менеджер | E1: Сотрудник | F1: Эшелон | G1: Брик | H1: Оценка (мп.), % | I1: Оценка общая (рук.), % | J1: Оценка эффективности коммуникации (рук.), % | K1: Оценка навыки продаж (рук.), % | L1: Динамика региона
A2: 32 | B2: Сибирь | C2: Алтайский край | D2: Миронова О.В. | E2: Чуданов В.Е. | F2: 8. ПРОРЕСПИ_РФ | H2: 0.54411765 | I2: 0.33823529 | J2: =VLOOKUP(E2,'Эффективная коммуникация оценка'!$E$1:$P$297,12,0) -> 0.35 | K2: =VLOOKUP(E2,'навыки техники продаж оценка'!$E$2:$P$297,12,0) -> 0.33333333 | L2: -9.0598291
A3: 156 | B3: Сибирь | C3: Алтайский край | D3: Миронова О.В. | E3: Егудина М.А. | F3: 8. ПРОСПЕЦ_РФ | I3: 0.58823529 | J3: =VLOOKUP(E3,'Эффективная коммуникация оценка'!$E$1:$P$297,12,0) -> 0.6 | K3: =VLOOKUP(E3,'навыки техники продаж оценка'!$E$2:$P$297,12,0) -> 0.58333333 | L3: -9.0598291
A4: 248 | B4: Сибирь | C4: Алтайский край | D4: Миронова О.В. | E4: Червова О.В. | F4: 8. ПРОРЕСПИ_РФ | H4: 0.55882353 | I4: 0.63235294 | J4: =VLOOKUP(E4,'Эффективная коммуникация оценка'!$E$1:$P$297,12,0) -> 0.65 | K4: =VLOOKUP(E4,'навыки техники продаж оценка'!$E$2:$P$297,12,0) -> 0.5 | L4: -9.0598291
A5: 255 | B5: Сибирь | C5: Алтайский край | D5: Миронова О.В. | E5: Петрова Е.А. | F5: 8. ПРОСПЕЦ_РФ | H5: 0.63235294 | I5: 0.58823529 | J5: =VLOOKUP(E5,'Эффективная коммуникация оценка'!$E$1:$P$297,12,0) -> 0.7 | K5: =VLOOKUP(E5,'навыки техники продаж оценка'!$E$2:$P$297,12,0) -> 0.58333333 | L5: -9.0598291
A6: 151 | B6: Северо-Запад | C6: Архангельская обл | D6: Евсеева М.Ю. | E6: Фролова Н.Г. | F6: 8. ПРОСПЕЦ_РФ | H6: 0.5 | I6: 0.55882353 | J6: =VLOOKUP(E6,'Эффективная коммуникация оценка'!$E$1:$P$297,12,0) -> 0.6 | K6: =VLOOKUP(E6,'навыки техники продаж оценка'!$E$2:$P$297,12,0) -> 0.5 | L6: 16.759213
A7: 188 | B7: Северо-Запад | C7: Архангельская обл | D7: Евсеева М.Ю. | E7: Данилюк Н.В. | F7: 8. ПРОРЕСПИ_РФ | H7: 0.52941176 | I7: 0.63235294 | J7: =VLOOKUP(E7,'Эффективная коммуникация оценка'!$E$1:$P$297,12,0) -> 0.75 | K7: =VLOOKUP(E7,'навыки техники продаж оценка'!$E$2:$P$297,12,0) -> 0.66666667 | L7: 16.759213
A8: 163 | B8: Юг | C8: Астраханская обл | D8: Петровская О.В. | E8: Хайрлиева Г.С. | F8: 8. ПРОСПЕЦ_РФ | H8: 0.64705882 | I8: 0.76470588 | J8: =VLOOKUP(E8,'Эффективная коммуникация оценка'!$E$1:$P$297,12,0) -> 0.8 | K8: =VLOOKUP(E8,'навыки техники продаж оценка'!$E$2:$P$297,12,0) -> 0.75 | L8: 22.505938
A9: 221 | B9: Юг | C9: Астраханская обл | D9: Петровская О.В. | E9: Вострикова З.Ф. | F9: 8. ПРОРЕСПИ_РФ | H9: 0.51470588 | I9: 0.67647059 | J9: =VLOOKUP(E9,'Эффективная коммуникация оценка'!$E$1:$P$297,12,0) -> 0.7 | K9: =VLOOKUP(E9,'навыки техники продаж оценка'!$E$2:$P$297,12,0) -> 0.58333333 | L9: 22.505938
A10: 13 | B10: Урал | C10: Башкортостан Респ | D10: Митяшева О.Б. | E10: Егорова И.В. | F10: 8. ПРОСПЕЦ_РФ | H10: 0.61764706 | I10: 0.80882353 | J10: =VLOOKUP(E10,'Эффективная коммуникация оценка'!$E$1:$P$297,12,0) -> 0.85 | K10: =VLOOKUP(E10,'навыки техники продаж оценка'!$E$2:$P$297,12,0) -> 0.66666667 | L10: -7.7609791
A11: 15 | B11: Урал | C11: Башкортостан Респ | D11: Митяшева О.Б. | E11: Якушева А.А. | F11: 8. ПРОСПЕЦ_РФ | H11: 0.45588235 | I11: 0.63235294 | J11: =VLOOKUP(E11,'Эффективная коммуникация оценка'!$E$1:$P$297,12,0) -> 0.7 | K11: =VLOOKUP(E11,'навыки техники продаж оценка'!$E$2:$P$297,12,0) -> 0.58333333 | L11: -7.7609791
A12: 31 | B12: Урал | C12: Башкортостан Респ | D12: Машукова О.М. | E12: Ваняшкина Е.С. | F12: 8. ПРОРЕСПИ_РФ | H12: 0.38235294 | I12: 0.38235294 | J12: =VLOOKUP(E12,'Эффективная коммуникация оценка'!$E$1:$P$297,12,0) -> 0.45 | K12: =VLOOKUP(E12,'навыки техники продаж оценка'!$E$2:$P$297,12,0) -> 0.33333333 | L12: -7.7609791
A13: 49 | B13: Урал | C13: Башкортостан Респ | D13: Машукова О.М. | E13: Курбангулова Г.Ю. | F13: 8. ПРОРЕСПИ_РФ | H13: 0.52941176 | I13: 0.60294118 | J13: =VLOOKUP(E13,'Эффективная коммуникация оценка'!$E$1:$P$297,12,0) -> 0.75 | K13: =VLOOKUP(E13,'навыки техники продаж оценка'!$E$2:$P$297,12,0) -> 0.58333333 | L13: -7.7609791
A14: 132 | B14: Урал | C14: Башкортостан Респ | D14: Митяшева О.Б. | E14: Зегер Е.О. | F14: 8. ПРОСПЕЦ_РФ | H14: 0.69117647 | I14: 0.86764706 | J14: =VLOOKUP(E14,'Эффективная коммуникация оценка'!$E$1:$P$297,12,0) -> 0.9 | K14: =VLOOKUP(E14,'навыки техники продаж оценка'!$E$2:$P$297,12,0) -> 0.66666667 | L14: -7.7609791
A15: 164 | B15: Урал | C15: Башкортостан Респ | D15: Машукова О.М. | E15: Шастова И.С. | F15: 8. ПРОРЕСПИ_РФ | H15: 0.67647059 | I15: 0.83823529 | J15: =VLOOKUP(E15,'Эффективная коммуникация оценка'!$E$1:$P$297,12,0) -> 0.95 | K15: =VLOOKUP(E15,'навыки техники продаж оценка'!$E$2:$P$297,12,0) -> 0.75 | L15: -7.7609791
... A81: 238 | B81: Центр | C81: Липецкая обл | D81: Окунев И.М. | E81: Гранкина Г.И. | F81: 8. ПРОРЕСПИ_РФ | H81: 0.60294118 | I81: 0.70588235 | J81: =VLOOKUP(E81,'Эффективная коммуникация оценка'!$E$1:$P$297,12,0) -> 0.7 | K81: =VLOOKUP(E81,'навыки техники продаж оценка'!$E$2:$P$297,12,0) -> 0.5 | L81: 1.1928429
A82: 0 | B82: Москва | C82: ПроРеспи М4 Восток | D82: Мальцева А.А. | E82: Абазова А.С. | F82: 8. ПРОРЕСПИ_РФ | H82: 0.55882353 | I82: 0.55882353 | J82: =VLOOKUP(E82,'Эффективная коммуникация оценка'!$E$1:$P$297,12,0) -> 0.4 | K82: =VLOOKUP(E82,'навыки техники продаж оценка'!$E$2:$P$297,12,0) -> 0.58333333 | L82: -0.92165899 | M82: 100
A83: 16 | B83: Москва | C83: ПроРеспи М10 Юго-Запад | D83: Кавунова И.Г. | E83: Антонов Д.А. | F83: 8. ПРОРЕСПИ_РФ | H83: 0.55882353 | I83: 0.64705882 | J83: =VLOOKUP(E83,'Эффективная коммуникация оценка'!$E$1:$P$297,12,0) -> 0.65 | K83: =VLOOKUP(E83,'навыки техники продаж оценка'!$E$2:$P$297,12,0) -> 0.58333333 | L83: -10.733591
A84: 21 | B84: Москва | C84: ПроРеспи М16 Север | D84: Котельникова Е.Б. | E84: Бодрова А.В. | F84: 8. ПРОРЕСПИ_РФ | H84: 0.72058824 | I84: 0.73529412 | J84: =VLOOKUP(E84,'Эффективная коммуникация оценка'!$E$1:$P$297,12,0) -> 0.65 | K84: =VLOOKUP(E84,'навыки техники продаж оценка'!$E$2:$P$297,12,0) -> 0.75 | L84: 31.108498
A85: 47 | B85: Москва | C85: ПроРеспи МО9 ТиНАО | D85: Скрылев А.В. | E85: Прищеп Л.П. | F85: 8. ПРОРЕСПИ_РФ | H85: 0.60294118 | I85: 0.75 | J85: =VLOOKUP(E85,'Эффективная коммуникация оценка'!$E$1:$P$297,12,0) -> 0.8 | K85: =VLOOKUP(E85,'навыки техники продаж оценка'!$E$2:$P$297,12,0) -> 0.66666667 | L85: 22.637238
A86: 60 | B86: Москва | C86: ПроРеспи М1 Восток | D86: Мальцева А.А. | E86: Афанасьева Ю.А. | F86: 8. ПРОРЕСПИ_РФ | H86: 0.52941176 | I86: 0.66176471 | J86: =VLOOKUP(E86,'Эффективная коммуникация оценка'!$E$1:$P$297,12,0) -> 0.7 | K86: =VLOOKUP(E86,'навыки техники продаж оценка'!$E$2:$P$297,12,0) -> 0.66666667 | L86: 26.521164
A87: 75 | B87: Москва | C87: ПроРеспи М14 Юг | D87: Кавунова И.Г. | E87: Семенова Т.Н. | F87: 8. ПРОРЕСПИ_РФ | H87: 0.52941176 | I87: 0.58823529 | J87: =VLOOKUP(E87,'Эффективная коммуникация оценка'!$E$1:$P$297,12,0) -> 0.6 | K87: =VLOOKUP(E87,'навыки техники продаж оценка'!$E$2:$P$297,12,0) -> 0.5 | L87: -17.442778
A88: 78 | B88: Москва | C88: ПроРеспи М11 Юго-Запад | D88: Кавунова И.Г. | E88: Разгуляева Т.А. | F88: 8. ПРОРЕСПИ_РФ | H88: 0.58823529 | I88: 0.64705882 | J88: =VLOOKUP(E88,'Эффективная коммуникация оценка'!$E$1:$P$297,12,0) -> 0.6 | K88: =VLOOKUP(E88,'навыки техники продаж оценка'!$E$2:$P$297,12,0) -> 0.58333333 | L88: -17.258883
A89: 86 | B89: Москва | C89: ПроРеспи М15 Север | D89: Котельникова Е.Б. | E89: Каминский Н.В. | F89: 8. ПРОРЕСПИ_РФ | H89: 0.5 | I89: 0.66176471 | J89: =VLOOKUP(E89,'Эффективная коммуникация оценка'!$E$1:$P$297,12,0) -> 0.55 | K89: =VLOOKUP(E89,'навыки техники продаж оценка'!$E$2:$P$297,12,0) -> 0.5 | L89: -15.962441
A90: 95 | B90: Москва | C90: ПроРеспи М2 Юго-Восток | D90: Мальцева А.А. | E90: Дмитраш А.В. | F90: 8. ПРОРЕСПИ_РФ | H90: 0.35294118 | I90: 0.54411765 | J90: =VLOOKUP(E90,'Эффективная коммуникация оценка'!$E$1:$P$297,12,0) -> 0.55 | K90: =VLOOKUP(E90,'навыки техники продаж оценка'!$E$2:$P$297,12,0) -> 0.58333333 | L90: -18.373151
A91: 99 | B91: Москва | C91: ПроСпец М5 Центр | D91: Мальцева А.А. | E91: Козырева Е.Н. | F91: 8. ПРОСПЕЦ_РФ | H91: 0.55882353 | I91: 0.52941176 | J91: =VLOOKUP(E91,'Эффективная коммуникация оценка'!$E$1:$P$297,12,0) -> 0.6 | K91: =VLOOKUP(E91,'навыки техники продаж оценка'!$E$2:$P$297,12,0) -> 0.5 | L91: 10.793494
A92: 100 | B92: Москва | C92: ПроРеспи М20 Северо-Восток | D92: Котельникова Е.Б. | E92: Кабатова И.А. | F92: 8. ПРОРЕСПИ_РФ | H92: 0.66176471 | I92: 0.69117647 | J92: =VLOOKUP(E92,'Эффективная коммуникация оценка'!$E$1:$P$297,12,0) -> 0.7 | K92: =VLOOKUP(E92,'навыки техники продаж оценка'!$E$2:$P$297,12,0) -> 0.75 | L92: 4.1237113
A93: 112 | B93: Москва | C93: ПроСпец М8 Юго-Восток | D93: Мальцева А.А. | E93: Кравцова А.С. | F93: 8. ПРОСПЕЦ_РФ | I93: 0.51470588 | J93: =VLOOKUP(E93,'Эффективная коммуникация оценка'!$E$1:$P$297,12,0) -> 0.55 | K93: =VLOOKUP(E93,'навыки техники продаж оценка'!$E$2:$P$297,12,0) -> 0.5 | L93: -22.37055
A94: 130 | B94: Москва | C94: ПроРеспи М7 Запад | D94: Кавунова И.Г. | E94: Иванова А.В. | F94: 8. ПРОРЕСПИ_РФ | H94: 0.54411765 | I94: 0.60294118 | J94: =VLOOKUP(E94,'Эффективная коммуникация оценка'!$E$1:$P$297,12,0) -> 0.65 | K94: =VLOOKUP(E94,'навыки техники продаж оценка'!$E$2:$P$297,12,0) -> 0.58333333 | L94: -9.0217942
A95: 134 | B95: Москва | C95: ПроСпец М6 Центр | D95: Мальцева А.А. | E95: Нефедова Э.С. | F95: 8. ПРОСПЕЦ_РФ | I95: 0.44117647 | J95: =VLOOKUP(E95,'Эффективная коммуникация оценка'!$E$1:$P$297,12,0) -> 0.4 | K95: =VLOOKUP(E95,'навыки техники продаж оценка'!$E$2:$P$297,12,0) -> 0.25 | L95: 13.458188
A96: 159 | B96: Москва | C96: ПроСпец М3 Юг | D96: Кавунова И.Г. | E96: Стрельникова М.Ю. | F96: 8. ПРОСПЕЦ_РФ | I96: 0.73529412 | J96: =VLOOKUP(E96,'Эффективная коммуникация оценка'!$E$1:$P$297,12,0) -> 0.7 | K96: =VLOOKUP(E96,'навыки техники продаж оценка'!$E$2:$P$297,12,0) -> 0.75 | L96: -10.719132
A97: 168 | B97: Москва | C97: ПроРеспи М3 Восток | D97: Котельникова Е.Б. | E97: Каманова А.А. | F97: 8. ПРОРЕСПИ_РФ | H97: 0.54411765 | I97: 0.64705882 | J97: =VLOOKUP(E97,'Эффективная коммуникация оценка'!$E$1:$P$297,12,0) -> 0.65 | K97: =VLOOKUP(E97,'навыки техники продаж оценка'!$E$2:$P$297,12,0) -> 0.5 | L97: 2.5290499
A98: 169 | B98: Москва | C98: ПроСпец М11 Северо-Восток | D98: Котельникова Е.Б. | E98: Егорова Т.И. | F98: 8. ПРОСПЕЦ_РФ | H98: 0.48529412 | I98: 0.67647059 | J98: =VLOOKUP(E98,'Эффективная коммуникация оценка'!$E$1:$P$297,12,0) -> 0.65 | K98: =VLOOKUP(E98,'навыки техники продаж оценка'!$E$2:$P$297,12,0) -> 0.58333333 | L98: -5.78125
A99: 190 | B99: Москва | C99: ПроСпец МО8 ТиНАО | D99: Скрылев А.В. | E99: Гарматин В.О. | F99: 8. ПРОСПЕЦ_РФ | I99: 0.5 | J99: =VLOOKUP(E99,'Эффективная коммуникация оценка'!$E$1:$P$297,12,0) -> 0.4 | K99: =VLOOKUP(E99,'навыки техники продаж оценка'!$E$2:$P$297,12,0) -> 0.58333333 | L99: 22.637238
A100: 202 | B100: Москва | C100: ПроРеспи М17 Северо-Запад | D100: Котельникова Е.Б. | E100: Грязнова О.А. | F100: 8. ПРОРЕСПИ_РФ | H100: 0.69117647 | I100: 0.69117647 | J100: =VLOOKUP(E100,'Эффективная коммуникация оценка'!$E$1:$P$297,12,0) -> 0.6 | K100: =VLOOKUP(E100,'навыки техники продаж оценка'!$E$2:$P$297,12,0) -> 0.58333333 | L100: -12.935954
A101: 210 | B101: Москва | C101: ПроРеспи М12 Юг | D101: Кавунова И.Г. | E101: Селезнева Ю.В. | F101: 8. ПРОРЕСПИ_РФ | H101: 0.57352941 | I101: 0.55882353 | J101: =VLOOKUP(E101,'Эффективная коммуникация оценка'!$E$1:$P$297,12,0) -> 0.55 | K101: =VLOOKUP(E101,'навыки техники продаж оценка'!$E$2:$P$297,12,0) -> 0.66666667 | L101: 5.7471264
A102: 212 | B102: Москва | C102: ПроРеспи М5 Центр | D102: Мальцева А.А. | E102: Юрова А.В. | F102: 8. ПРОРЕСПИ_РФ | H102: 0.5 | I102: 0.60294118 | J102: =VLOOKUP(E102,'Эффективная коммуникация оценка'!$E$1:$P$297,12,0) -> 0.6 | K102: =VLOOKUP(E102,'навыки техники продаж оценка'!$E$2:$P$297,12,0) -> 0.58333333 | L102: 13.458188
A103: 218 | B103: Москва | C103: ПроСпец М10 Восток-Северо-Восток | D103: Котельникова Е.Б. | E103: Касимова М.М. | F103: 8. ПРОСПЕЦ_РФ | H103: 0.75 | I103: 0.63235294 | J103: =VLOOKUP(E103,'Эффективная коммуникация оценка'!$E$1:$P$297,12,0) -> 0.8 | K103: =VLOOKUP(E103,'навыки техники продаж оценка'!$E$2:$P$297,12,0) -> 0.58333333 | L103: -5.5555556
A104: 219 | B104: Москва | C104: ПроРеспи М6 Центр | D104: Мальцева А.А. | E104: Шебалкова Т.Н. | F104: 8. ПРОРЕСПИ_РФ | H104: 0.60294118 | I104: 0.83823529 | J104: =VLOOKUP(E104,'Эффективная коммуникация оценка'!$E$1:$P$297,12,0) -> 0.85 | K104: =VLOOKUP(E104,'навыки техники продаж оценка'!$E$2:$P$297,12,0) -> 0.91666667 | L104: 10.793494
A105: 234 | B105: Москва | C105: ПроСпец М7 Восток | D105: Мальцева А.А. | E105: Сагиндыкова Д.А. | F105: 8. ПРОСПЕЦ_РФ | H105: 0.42647059 | I105: 0.58823529 | J105: =VLOOKUP(E105,'Эффективная коммуникация оценка'!$E$1:$P$297,12,0) -> 0.55 | K105: =VLOOKUP(E105,'навыки техники продаж оценка'!$E$2:$P$297,12,0) -> 0.58333333 | L105: -0.16319869
...

Sheet ПРОСПЕКТА_регионы
B1: Регион ММХ | C1: Область | D1: Менеджер | E1: Сотрудник | F1: Эшелон | H1: Оценка (мп.), % | I1: Оценка общая (рук.), % | J1: Оценка эффективности коммуникации (рук.), % | K1: Оценка навыки продаж (рук.), % | L1: Выполнение плана | M1: Динамика региона
A2: 32 | B2: Сибирь | C2: Алтайский край | D2: Миронова О.В. | E2: Чуданов В.Е. | F2: 8. ПРОРЕСПИ_РФ | H2: 0.54411765 | I2: 0.33823529 | J2: =VLOOKUP(E2,'Эффективная коммуникация оценка'!$E$1:$P$297,12,0) -> 0.35 | K2: =VLOOKUP(E2,'навыки техники продаж оценка'!$E$2:$P$297,12,0) -> 0.33333333 | L2: 73.382393 | M2: 14.355639
A3: 156 | B3: Сибирь | C3: Алтайский край | D3: Миронова О.В. | E3: Егудина М.А. | F3: 8. ПРОСПЕЦ_РФ | I3: 0.58823529 | J3: =VLOOKUP(E3,'Эффективная коммуникация оценка'!$E$1:$P$297,12,0) -> 0.6 | K3: =VLOOKUP(E3,'навыки техники продаж оценка'!$E$2:$P$297,12,0) -> 0.58333333 | L3: 73.382393 | M3: 14.355639
A4: 248 | B4: Сибирь | C4: Алтайский край | D4: Миронова О.В. | E4: Червова О.В. | F4: 8. ПРОРЕСПИ_РФ | H4: 0.55882353 | I4: 0.63235294 | J4: =VLOOKUP(E4,'Эффективная коммуникация оценка'!$E$1:$P$297,12,0) -> 0.65 | K4: =VLOOKUP(E4,'навыки техники продаж оценка'!$E$2:$P$297,12,0) -> 0.5 | L4: 73.382393 | M4: 14.355639
A5: 255 | B5: Сибирь | C5: Алтайский край | D5: Миронова О.В. | E5: Петрова Е.А. | F5: 8. ПРОСПЕЦ_РФ | H5: 0.63235294 | I5: 0.58823529 | J5: =VLOOKUP(E5,'Эффективная коммуникация оценка'!$E$1:$P$297,12,0) -> 0.7 | K5: =VLOOKUP(E5,'навыки техники продаж оценка'!$E$2:$P$297,12,0) -> 0.58333333 | L5: 73.382393 | M5: 14.355639
A6: 151 | B6: Северо-Запад | C6: Архангельская обл | D6: Евсеева М.Ю. | E6: Фролова Н.Г. | F6: 8. ПРОСПЕЦ_РФ | H6: 0.5 | I6: 0.55882353 | J6: =VLOOKUP(E6,'Эффективная коммуникация оценка'!$E$1:$P$297,12,0) -> 0.6 | K6: =VLOOKUP(E6,'навыки техники продаж оценка'!$E$2:$P$297,12,0) -> 0.5 | L6: 78.088038 | M6: 17.310863
A7: 188 | B7: Северо-Запад | C7: Архангельская обл | D7: Евсеева М.Ю. | E7: Данилюк Н.В. | F7: 8. ПРОРЕСПИ_РФ | H7: 0.52941176 | I7: 0.63235294 | J7: =VLOOKUP(E7,'Эффективная коммуникация оценка'!$E$1:$P$297,12,0) -> 0.75 | K7: =VLOOKUP(E7,'навыки техники продаж оценка'!$E$2:$P$297,12,0) -> 0.66666667 | L7: 78.088038 | M7: 17.310863
A8: 163 | B8: Юг | C8: Астраханская обл | D8: Петровская О.В. | E8: Хайрлиева Г.С. | F8: 8. ПРОСПЕЦ_РФ | H8: 0.64705882 | I8: 0.76470588 | J8: =VLOOKUP(E8,'Эффективная коммуникация оценка'!$E$1:$P$297,12,0) -> 0.8 | K8: =VLOOKUP(E8,'навыки техники продаж оценка'!$E$2:$P$297,12,0) -> 0.75 | L8: 90.9648 | M8: 77.74993
A9: 221 | B9: Юг | C9: Астраханская обл | D9: Петровская О.В. | E9: Вострикова З.Ф. | F9: 8. ПРОРЕСПИ_РФ | H9: 0.51470588 | I9: 0.67647059 | J9: =VLOOKUP(E9,'Эффективная коммуникация оценка'!$E$1:$P$297,12,0) -> 0.7 | K9: =VLOOKUP(E9,'навыки техники продаж оценка'!$E$2:$P$297,12,0) -> 0.58333333 | L9: 90.9648 | M9: 77.74993
A10: 13 | B10: Урал | C10: Башкортостан Респ | D10: Митяшева О.Б. | E10: Егорова И.В. | F10: 8. ПРОСПЕЦ_РФ | H10: 0.61764706 | I10: 0.80882353 | J10: =VLOOKUP(E10,'Эффективная коммуникация оценка'!$E$1:$P$297,12,0) -> 0.85 | K10: =VLOOKUP(E10,'навыки техники продаж оценка'!$E$2:$P$297,12,0) -> 0.66666667 | L10: 71.421748 | M10: 21.683936
A11: 15 | B11: Урал | C11: Башкортостан Респ | D11: Митяшева О.Б. | E11: Якушева А.А. | F11: 8. ПРОСПЕЦ_РФ | H11: 0.45588235 | I11: 0.63235294 | J11: =VLOOKUP(E11,'Эффективная коммуникация оценка'!$E$1:$P$297,12,0) -> 0.7 | K11: =VLOOKUP(E11,'навыки техники продаж оценка'!$E$2:$P$297,12,0) -> 0.58333333 | L11: 71.421748 | M11: 21.683936
A12: 31 | B12: Урал | C12: Башкортостан Респ | D12: Машукова О.М. | E12: Ваняшкина Е.С. | F12: 8. ПРОРЕСПИ_РФ | H12: 0.38235294 | I12: 0.38235294 | J12: =VLOOKUP(E12,'Эффективная коммуникация оценка'!$E$1:$P$297,12,0) -> 0.45 | K12: =VLOOKUP(E12,'навыки техники продаж оценка'!$E$2:$P$297,12,0) -> 0.33333333 | L12: 71.421748 | M12: 21.683936
A13: 49 | B13: Урал | C13: Башкортостан Респ | D13: Машукова О.М. | E13: Курбангулова Г.Ю. | F13: 8. ПРОРЕСПИ_РФ | H13: 0.52941176 | I13: 0.60294118 | J13: =VLOOKUP(E13,'Эффективная коммуникация оценка'!$E$1:$P$297,12,0) -> 0.75 | K13: =VLOOKUP(E13,'навыки техники продаж оценка'!$E$2:$P$297,12,0) -> 0.58333333 | L13: 71.421748 | M13: 21.683936
A14: 132 | B14: Урал | C14: Башкортостан Респ | D14: Митяшева О.Б. | E14: Зегер Е.О. | F14: 8. ПРОСПЕЦ_РФ | H14: 0.69117647 | I14: 0.86764706 | J14: =VLOOKUP(E14,'Эффективная коммуникация оценка'!$E$1:$P$297,12,0) -> 0.9 | K14: =VLOOKUP(E14,'навыки техники продаж оценка'!$E$2:$P$297,12,0) -> 0.66666667 | L14: 71.421748 | M14: 21.683936
A15: 164 | B15: Урал | C15: Башкортостан Респ | D15: Машукова О.М. | E15: Шастова И.С. | F15: 8. ПРОРЕСПИ_РФ | H15: 0.67647059 | I15: 0.83823529 | J15: =VLOOKUP(E15,'Эффективная коммуникация оценка'!$E$1:$P$297,12,0) -> 0.95 | K15: =VLOOKUP(E15,'навыки техники продаж оценка'!$E$2:$P$297,12,0) -> 0.75 | L15: 71.421748 | M15: 21.683936
... A92: 100 | B92: Москва | C92: Москва г | D92: Котельникова Е.Б. | E92: Кабатова И.А. | F92: 8. ПРОРЕСПИ_РФ | H92: 0.66176471 | I92: 0.69117647 | J92: =VLOOKUP(E92,'Эффективная коммуникация оценка'!$E$1:$P$297,12,0) -> 0.7 | K92: =VLOOKUP(E92,'навыки техники продаж оценка'!$E$2:$P$297,12,0) -> 0.75 | L92: 62.882604 | M92: 33.032787
A93: 112 | B93: Москва | C93: Москва г | D93: Мальцева А.А. | E93: Кравцова А.С. | F93: 8. ПРОСПЕЦ_РФ | I93: 0.51470588 | J93: =VLOOKUP(E93,'Эффективная коммуникация оценка'!$E$1:$P$297,12,0) -> 0.55 | K93: =VLOOKUP(E93,'навыки техники продаж оценка'!$E$2:$P$297,12,0) -> 0.5 | L93: 62.882604 | M93: 33.032787
A94: 130 | B94: Москва | C94: Москва г | D94: Кавунова И.Г. | E94: Иванова А.В. | F94: 8. ПРОРЕСПИ_РФ | H94: 0.54411765 | I94: 0.60294118 | J94: =VLOOKUP(E94,'Эффективная коммуникация оценка'!$E$1:$P$297,12,0) -> 0.65 | K94: =VLOOKUP(E94,'навыки техники продаж оценка'!$E$2:$P$297,12,0) -> 0.58333333 | L94: 62.882604 | M94: 33.032787
A95: 134 | B95: Москва | C95: Москва г | D95: Мальцева А.А. | E95: Нефедова Э.С. | F95: 8. ПРОСПЕЦ_РФ | I95: 0.44117647 | J95: =VLOOKUP(E95,'Эффективная коммуникация оценка'!$E$1:$P$297,12,0) -> 0.4 | K95: =VLOOKUP(E95,'навыки техники продаж оценка'!$E$2:$P$297,12,0) -> 0.25 | L95: 62.882604 | M95: 33.032787
A96: 159 | B96: Москва | C96: Москва г | D96: Кавунова И.Г. | E96: Стрельникова М.Ю. | F96: 8. ПРОСПЕЦ_РФ | I96: 0.73529412 | J96: =VLOOKUP(E96,'Эффективная коммуникация оценка'!$E$1:$P$297,12,0) -> 0.7 | K96: =VLOOKUP(E96,'навыки техники продаж оценка'!$E$2:$P$297,12,0) -> 0.75 | L96: 62.882604 | M96: 33.032787
A97: 168 | B97: Москва | C97: Москва г | D97: Котельникова Е.Б. | E97: Каманова А.А. | F97: 8. ПРОРЕСПИ_РФ | H97: 0.54411765 | I97: 0.64705882 | J97: =VLOOKUP(E97,'Эффективная коммуникация оценка'!$E$1:$P$297,12,0) -> 0.65 | K97: =VLOOKUP(E97,'навыки техники продаж оценка'!$E$2:$P$297,12,0) -> 0.5 | L97: 62.882604 | M97: 33.032787
